Exception on /q [GET]
Traceback (most recent call last):
  File "/Users/Joel/Sites/gitApps/venv/lib/python2.7/site-packages/flask/app.py", line 1817, in wsgi_app
    response = self.full_dispatch_request()
  File "/Users/Joel/Sites/gitApps/venv/lib/python2.7/site-packages/flask/app.py", line 1478, in full_dispatch_request
    response = self.make_response(rv)
  File "/Users/Joel/Sites/gitApps/venv/lib/python2.7/site-packages/flask/app.py", line 1577, in make_response
    rv = self.response_class.force_type(rv, request.environ)
  File "/Users/Joel/Sites/gitApps/venv/lib/python2.7/site-packages/werkzeug/wrappers.py", line 824, in force_type
    response = BaseResponse(*_run_wsgi_app(response, environ))
  File "/Users/Joel/Sites/gitApps/venv/lib/python2.7/site-packages/werkzeug/wrappers.py", line 57, in _run_wsgi_app
    return _run_wsgi_app(*args)
  File "/Users/Joel/Sites/gitApps/venv/lib/python2.7/site-packages/werkzeug/test.py", line 854, in run_wsgi_app
    app_iter = app(environ, start_response)
TypeError: 'dict' object is not callable
'dict' object is not callable
Traceback (most recent call last):
  File "/Users/Joel/Sites/gitApps/venv/lib/python2.7/site-packages/flask/app.py", line 1817, in wsgi_app
    response = self.full_dispatch_request()
  File "/Users/Joel/Sites/gitApps/venv/lib/python2.7/site-packages/flask/app.py", line 1478, in full_dispatch_request
    response = self.make_response(rv)
  File "/Users/Joel/Sites/gitApps/venv/lib/python2.7/site-packages/flask/app.py", line 1577, in make_response
    rv = self.response_class.force_type(rv, request.environ)
  File "/Users/Joel/Sites/gitApps/venv/lib/python2.7/site-packages/werkzeug/wrappers.py", line 824, in force_type
    response = BaseResponse(*_run_wsgi_app(response, environ))
  File "/Users/Joel/Sites/gitApps/venv/lib/python2.7/site-packages/werkzeug/wrappers.py", line 57, in _run_wsgi_app
    return _run_wsgi_app(*args)
  File "/Users/Joel/Sites/gitApps/venv/lib/python2.7/site-packages/werkzeug/test.py", line 854, in run_wsgi_app
    app_iter = app(environ, start_response)
TypeError: 'dict' object is not callable
Exception on /q [GET]
Traceback (most recent call last):
  File "/Users/Joel/Sites/gitApps/venv/lib/python2.7/site-packages/flask/app.py", line 1817, in wsgi_app
    response = self.full_dispatch_request()
  File "/Users/Joel/Sites/gitApps/venv/lib/python2.7/site-packages/flask/app.py", line 1478, in full_dispatch_request
    response = self.make_response(rv)
  File "/Users/Joel/Sites/gitApps/venv/lib/python2.7/site-packages/flask/app.py", line 1577, in make_response
    rv = self.response_class.force_type(rv, request.environ)
  File "/Users/Joel/Sites/gitApps/venv/lib/python2.7/site-packages/werkzeug/wrappers.py", line 824, in force_type
    response = BaseResponse(*_run_wsgi_app(response, environ))
  File "/Users/Joel/Sites/gitApps/venv/lib/python2.7/site-packages/werkzeug/test.py", line 854, in run_wsgi_app
    app_iter = app(environ, start_response)
TypeError: 'dict' object is not callable
'dict' object is not callable
Traceback (most recent call last):
  File "/Users/Joel/Sites/gitApps/venv/lib/python2.7/site-packages/flask/app.py", line 1817, in wsgi_app
    response = self.full_dispatch_request()
  File "/Users/Joel/Sites/gitApps/venv/lib/python2.7/site-packages/flask/app.py", line 1478, in full_dispatch_request
    response = self.make_response(rv)
  File "/Users/Joel/Sites/gitApps/venv/lib/python2.7/site-packages/flask/app.py", line 1577, in make_response
    rv = self.response_class.force_type(rv, request.environ)
  File "/Users/Joel/Sites/gitApps/venv/lib/python2.7/site-packages/werkzeug/wrappers.py", line 824, in force_type
    response = BaseResponse(*_run_wsgi_app(response, environ))
  File "/Users/Joel/Sites/gitApps/venv/lib/python2.7/site-packages/werkzeug/test.py", line 854, in run_wsgi_app
    app_iter = app(environ, start_response)
TypeError: 'dict' object is not callable
Exception on /q [GET]
Traceback (most recent call last):
  File "/Users/Joel/Sites/gitApps/venv/lib/python2.7/site-packages/flask/app.py", line 1817, in wsgi_app
    response = self.full_dispatch_request()
  File "/Users/Joel/Sites/gitApps/venv/lib/python2.7/site-packages/flask/app.py", line 1478, in full_dispatch_request
    response = self.make_response(rv)
  File "/Users/Joel/Sites/gitApps/venv/lib/python2.7/site-packages/flask/app.py", line 1577, in make_response
    rv = self.response_class.force_type(rv, request.environ)
  File "/Users/Joel/Sites/gitApps/venv/lib/python2.7/site-packages/werkzeug/wrappers.py", line 824, in force_type
    response = BaseResponse(*_run_wsgi_app(response, environ))
  File "/Users/Joel/Sites/gitApps/venv/lib/python2.7/site-packages/werkzeug/test.py", line 854, in run_wsgi_app
    app_iter = app(environ, start_response)
TypeError: 'dict' object is not callable
'dict' object is not callable
Traceback (most recent call last):
  File "/Users/Joel/Sites/gitApps/venv/lib/python2.7/site-packages/flask/app.py", line 1817, in wsgi_app
    response = self.full_dispatch_request()
  File "/Users/Joel/Sites/gitApps/venv/lib/python2.7/site-packages/flask/app.py", line 1478, in full_dispatch_request
    response = self.make_response(rv)
  File "/Users/Joel/Sites/gitApps/venv/lib/python2.7/site-packages/flask/app.py", line 1577, in make_response
    rv = self.response_class.force_type(rv, request.environ)
  File "/Users/Joel/Sites/gitApps/venv/lib/python2.7/site-packages/werkzeug/wrappers.py", line 824, in force_type
    response = BaseResponse(*_run_wsgi_app(response, environ))
  File "/Users/Joel/Sites/gitApps/venv/lib/python2.7/site-packages/werkzeug/test.py", line 854, in run_wsgi_app
    app_iter = app(environ, start_response)
TypeError: 'dict' object is not callable
Exception on /q [GET]
Traceback (most recent call last):
  File "/Users/Joel/Sites/gitApps/venv/lib/python2.7/site-packages/flask/app.py", line 1817, in wsgi_app
    response = self.full_dispatch_request()
  File "/Users/Joel/Sites/gitApps/venv/lib/python2.7/site-packages/flask/app.py", line 1478, in full_dispatch_request
    response = self.make_response(rv)
  File "/Users/Joel/Sites/gitApps/venv/lib/python2.7/site-packages/flask/app.py", line 1577, in make_response
    rv = self.response_class.force_type(rv, request.environ)
  File "/Users/Joel/Sites/gitApps/venv/lib/python2.7/site-packages/werkzeug/wrappers.py", line 824, in force_type
    response = BaseResponse(*_run_wsgi_app(response, environ))
  File "/Users/Joel/Sites/gitApps/venv/lib/python2.7/site-packages/werkzeug/test.py", line 854, in run_wsgi_app
    app_iter = app(environ, start_response)
TypeError: 'dict' object is not callable
'dict' object is not callable
Traceback (most recent call last):
  File "/Users/Joel/Sites/gitApps/venv/lib/python2.7/site-packages/flask/app.py", line 1817, in wsgi_app
    response = self.full_dispatch_request()
  File "/Users/Joel/Sites/gitApps/venv/lib/python2.7/site-packages/flask/app.py", line 1478, in full_dispatch_request
    response = self.make_response(rv)
  File "/Users/Joel/Sites/gitApps/venv/lib/python2.7/site-packages/flask/app.py", line 1577, in make_response
    rv = self.response_class.force_type(rv, request.environ)
  File "/Users/Joel/Sites/gitApps/venv/lib/python2.7/site-packages/werkzeug/wrappers.py", line 824, in force_type
    response = BaseResponse(*_run_wsgi_app(response, environ))
  File "/Users/Joel/Sites/gitApps/venv/lib/python2.7/site-packages/werkzeug/test.py", line 854, in run_wsgi_app
    app_iter = app(environ, start_response)
TypeError: 'dict' object is not callable
Exception on /q [GET]
Traceback (most recent call last):
  File "/Users/Joel/Sites/gitApps/venv/lib/python2.7/site-packages/flask/app.py", line 1817, in wsgi_app
    response = self.full_dispatch_request()
  File "/Users/Joel/Sites/gitApps/venv/lib/python2.7/site-packages/flask/app.py", line 1478, in full_dispatch_request
    response = self.make_response(rv)
  File "/Users/Joel/Sites/gitApps/venv/lib/python2.7/site-packages/flask/app.py", line 1577, in make_response
    rv = self.response_class.force_type(rv, request.environ)
  File "/Users/Joel/Sites/gitApps/venv/lib/python2.7/site-packages/werkzeug/wrappers.py", line 824, in force_type
    response = BaseResponse(*_run_wsgi_app(response, environ))
  File "/Users/Joel/Sites/gitApps/venv/lib/python2.7/site-packages/werkzeug/test.py", line 854, in run_wsgi_app
    app_iter = app(environ, start_response)
TypeError: 'dict' object is not callable
'dict' object is not callable
Traceback (most recent call last):
  File "/Users/Joel/Sites/gitApps/venv/lib/python2.7/site-packages/flask/app.py", line 1817, in wsgi_app
    response = self.full_dispatch_request()
  File "/Users/Joel/Sites/gitApps/venv/lib/python2.7/site-packages/flask/app.py", line 1478, in full_dispatch_request
    response = self.make_response(rv)
  File "/Users/Joel/Sites/gitApps/venv/lib/python2.7/site-packages/flask/app.py", line 1577, in make_response
    rv = self.response_class.force_type(rv, request.environ)
  File "/Users/Joel/Sites/gitApps/venv/lib/python2.7/site-packages/werkzeug/wrappers.py", line 824, in force_type
    response = BaseResponse(*_run_wsgi_app(response, environ))
  File "/Users/Joel/Sites/gitApps/venv/lib/python2.7/site-packages/werkzeug/test.py", line 854, in run_wsgi_app
    app_iter = app(environ, start_response)
TypeError: 'dict' object is not callable
